[2020-10-29 10:48:06,732] {taskinstance.py:670} INFO - Dependencies all met for <TaskInstance: tutorial.TransformLoad 2020-10-29T05:16:43.319400+00:00 [queued]>
[2020-10-29 10:48:06,747] {taskinstance.py:670} INFO - Dependencies all met for <TaskInstance: tutorial.TransformLoad 2020-10-29T05:16:43.319400+00:00 [queued]>
[2020-10-29 10:48:06,747] {taskinstance.py:880} INFO - 
--------------------------------------------------------------------------------
[2020-10-29 10:48:06,747] {taskinstance.py:881} INFO - Starting attempt 1 of 2
[2020-10-29 10:48:06,748] {taskinstance.py:882} INFO - 
--------------------------------------------------------------------------------
[2020-10-29 10:48:06,754] {taskinstance.py:901} INFO - Executing <Task(PythonOperator): TransformLoad> on 2020-10-29T05:16:43.319400+00:00
[2020-10-29 10:48:06,756] {standard_task_runner.py:54} INFO - Started process 82268 to run task
[2020-10-29 10:48:06,783] {standard_task_runner.py:77} INFO - Running: ['airflow', 'run', 'tutorial', 'TransformLoad', '2020-10-29T05:16:43.319400+00:00', '--job_id', '285', '--pool', 'default_pool', '--raw', '-sd', 'DAGS_FOLDER/tutorial.py', '--cfg_path', '/var/folders/4j/yctg8njd19g2873bfk914jqw0000gn/T/tmp9rzil38a']
[2020-10-29 10:48:06,785] {standard_task_runner.py:78} INFO - Job 285: Subtask TransformLoad
[2020-10-29 10:48:11,814] {logging_mixin.py:112} INFO - Running %s on host %s <TaskInstance: tutorial.TransformLoad 2020-10-29T05:16:43.319400+00:00 [running]> Arpitas-MacBook-Pro.local
[2020-10-29 10:48:34,920] {taskinstance.py:1150} ERROR - name 'dest_conn' is not defined
Traceback (most recent call last):
  File "/Users/arpitasaha/opt/anaconda3/lib/python3.7/site-packages/airflow/models/taskinstance.py", line 984, in _run_raw_task
    result = task_copy.execute(context=context)
  File "/Users/arpitasaha/opt/anaconda3/lib/python3.7/site-packages/airflow/operators/python_operator.py", line 113, in execute
    return_value = self.execute_callable()
  File "/Users/arpitasaha/opt/anaconda3/lib/python3.7/site-packages/airflow/operators/python_operator.py", line 118, in execute_callable
    return self.python_callable(*self.op_args, **self.op_kwargs)
  File "/Users/arpitasaha/airflow/dags/tutorial.py", line 67, in transform_data
    dest_conn.executemany(sqlUpdate,data)
NameError: name 'dest_conn' is not defined
[2020-10-29 10:48:34,922] {taskinstance.py:1194} INFO - Marking task as UP_FOR_RETRY. dag_id=tutorial, task_id=TransformLoad, execution_date=20201029T051643, start_date=20201029T051806, end_date=20201029T051834
[2020-10-29 10:48:34,937] {configuration.py:338} WARNING - section/key [smtp/smtp_user] not found in config
[2020-10-29 10:48:34,940] {configuration.py:338} WARNING - section/key [smtp/smtp_user] not found in config
[2020-10-29 10:48:34,941] {taskinstance.py:1200} ERROR - Failed to send email to: ['arpita.b.saha@outlook.com']
[2020-10-29 10:48:34,941] {taskinstance.py:1201} ERROR - [Errno 61] Connection refused
Traceback (most recent call last):
  File "/Users/arpitasaha/opt/anaconda3/lib/python3.7/site-packages/airflow/models/taskinstance.py", line 984, in _run_raw_task
    result = task_copy.execute(context=context)
  File "/Users/arpitasaha/opt/anaconda3/lib/python3.7/site-packages/airflow/operators/python_operator.py", line 113, in execute
    return_value = self.execute_callable()
  File "/Users/arpitasaha/opt/anaconda3/lib/python3.7/site-packages/airflow/operators/python_operator.py", line 118, in execute_callable
    return self.python_callable(*self.op_args, **self.op_kwargs)
  File "/Users/arpitasaha/airflow/dags/tutorial.py", line 67, in transform_data
    dest_conn.executemany(sqlUpdate,data)
NameError: name 'dest_conn' is not defined

During handling of the above exception, another exception occurred:

Traceback (most recent call last):
  File "/Users/arpitasaha/opt/anaconda3/lib/python3.7/site-packages/airflow/models/taskinstance.py", line 1473, in email_alert
    send_email(self.task.email, subject, html_content)
  File "/Users/arpitasaha/opt/anaconda3/lib/python3.7/site-packages/airflow/utils/email.py", line 62, in send_email
    mime_subtype=mime_subtype, mime_charset=mime_charset, **kwargs)
  File "/Users/arpitasaha/opt/anaconda3/lib/python3.7/site-packages/airflow/utils/email.py", line 108, in send_email_smtp
    send_MIME_email(smtp_mail_from, recipients, msg, dryrun)
  File "/Users/arpitasaha/opt/anaconda3/lib/python3.7/site-packages/airflow/utils/email.py", line 127, in send_MIME_email
    s = smtplib.SMTP_SSL(SMTP_HOST, SMTP_PORT) if SMTP_SSL else smtplib.SMTP(SMTP_HOST, SMTP_PORT)
  File "/Users/arpitasaha/opt/anaconda3/lib/python3.7/smtplib.py", line 251, in __init__
    (code, msg) = self.connect(host, port)
  File "/Users/arpitasaha/opt/anaconda3/lib/python3.7/smtplib.py", line 336, in connect
    self.sock = self._get_socket(host, port, self.timeout)
  File "/Users/arpitasaha/opt/anaconda3/lib/python3.7/smtplib.py", line 307, in _get_socket
    self.source_address)
  File "/Users/arpitasaha/opt/anaconda3/lib/python3.7/socket.py", line 728, in create_connection
    raise err
  File "/Users/arpitasaha/opt/anaconda3/lib/python3.7/socket.py", line 716, in create_connection
    sock.connect(sa)
ConnectionRefusedError: [Errno 61] Connection refused

During handling of the above exception, another exception occurred:

Traceback (most recent call last):
  File "/Users/arpitasaha/opt/anaconda3/lib/python3.7/site-packages/airflow/models/taskinstance.py", line 1198, in handle_failure
    self.email_alert(error)
  File "/Users/arpitasaha/opt/anaconda3/lib/python3.7/site-packages/airflow/models/taskinstance.py", line 1475, in email_alert
    send_email(self.task.email, subject, html_content_err)
  File "/Users/arpitasaha/opt/anaconda3/lib/python3.7/site-packages/airflow/utils/email.py", line 62, in send_email
    mime_subtype=mime_subtype, mime_charset=mime_charset, **kwargs)
  File "/Users/arpitasaha/opt/anaconda3/lib/python3.7/site-packages/airflow/utils/email.py", line 108, in send_email_smtp
    send_MIME_email(smtp_mail_from, recipients, msg, dryrun)
  File "/Users/arpitasaha/opt/anaconda3/lib/python3.7/site-packages/airflow/utils/email.py", line 127, in send_MIME_email
    s = smtplib.SMTP_SSL(SMTP_HOST, SMTP_PORT) if SMTP_SSL else smtplib.SMTP(SMTP_HOST, SMTP_PORT)
  File "/Users/arpitasaha/opt/anaconda3/lib/python3.7/smtplib.py", line 251, in __init__
    (code, msg) = self.connect(host, port)
  File "/Users/arpitasaha/opt/anaconda3/lib/python3.7/smtplib.py", line 336, in connect
    self.sock = self._get_socket(host, port, self.timeout)
  File "/Users/arpitasaha/opt/anaconda3/lib/python3.7/smtplib.py", line 307, in _get_socket
    self.source_address)
  File "/Users/arpitasaha/opt/anaconda3/lib/python3.7/socket.py", line 728, in create_connection
    raise err
  File "/Users/arpitasaha/opt/anaconda3/lib/python3.7/socket.py", line 716, in create_connection
    sock.connect(sa)
ConnectionRefusedError: [Errno 61] Connection refused
[2020-10-29 10:48:36,857] {local_task_job.py:102} INFO - Task exited with return code 1
