[2020-10-19 22:16:09,073] {taskinstance.py:670} INFO - Dependencies all met for <TaskInstance: tutorial.sqlite_to_df 2020-10-19T16:30:15.912664+00:00 [queued]>
[2020-10-19 22:16:09,078] {taskinstance.py:670} INFO - Dependencies all met for <TaskInstance: tutorial.sqlite_to_df 2020-10-19T16:30:15.912664+00:00 [queued]>
[2020-10-19 22:16:09,078] {taskinstance.py:880} INFO - 
--------------------------------------------------------------------------------
[2020-10-19 22:16:09,078] {taskinstance.py:881} INFO - Starting attempt 2 of 2
[2020-10-19 22:16:09,078] {taskinstance.py:882} INFO - 
--------------------------------------------------------------------------------
[2020-10-19 22:16:09,084] {taskinstance.py:901} INFO - Executing <Task(PythonOperator): sqlite_to_df> on 2020-10-19T16:30:15.912664+00:00
[2020-10-19 22:16:09,086] {standard_task_runner.py:54} INFO - Started process 17194 to run task
[2020-10-19 22:16:09,105] {standard_task_runner.py:77} INFO - Running: ['airflow', 'run', 'tutorial', 'sqlite_to_df', '2020-10-19T16:30:15.912664+00:00', '--job_id', '278', '--pool', 'default_pool', '--raw', '-sd', 'DAGS_FOLDER/tutorial.py', '--cfg_path', '/var/folders/4j/yctg8njd19g2873bfk914jqw0000gn/T/tmpqjjgq2s4']
[2020-10-19 22:16:09,106] {standard_task_runner.py:78} INFO - Job 278: Subtask sqlite_to_df
[2020-10-19 22:16:09,135] {logging_mixin.py:112} INFO - Running %s on host %s <TaskInstance: tutorial.sqlite_to_df 2020-10-19T16:30:15.912664+00:00 [running]> Arpitas-MacBook-Pro.local
[2020-10-19 22:16:09,149] {base_hook.py:89} INFO - Using connection to: id: sqlite_default. Host: /Users/arpitasaha/airflow/dags/db/B2BPlatform.db, Port: None, Schema: /Users/arpitasaha/airflow/dags/db/B2BPlatform.db, Login: None, Password: None, extra: None
[2020-10-19 22:16:09,149] {taskinstance.py:1150} ERROR - unable to open database file
Traceback (most recent call last):
  File "/Users/arpitasaha/opt/anaconda3/lib/python3.7/site-packages/airflow/models/taskinstance.py", line 984, in _run_raw_task
    result = task_copy.execute(context=context)
  File "/Users/arpitasaha/opt/anaconda3/lib/python3.7/site-packages/airflow/operators/python_operator.py", line 113, in execute
    return_value = self.execute_callable()
  File "/Users/arpitasaha/opt/anaconda3/lib/python3.7/site-packages/airflow/operators/python_operator.py", line 118, in execute_callable
    return self.python_callable(*self.op_args, **self.op_kwargs)
  File "/Users/arpitasaha/airflow/dags/tutorial.py", line 144, in getdf
    df = h.get_pandas_df("SELECT A.DocumentNo, A.FullName, A.Device, A.Country, B.OrderId, B.DocumentNo, B.OrderDate, B.CatalogId,C.CatalogId, C.ProductId, C.CUID, D.ProductId, D.ProductName, D.CUID FROM CUSTOMERS as A inner join ORDERS as B on A.DocumentNo = B.DocumentNo inner join CATALOG as C on C.CatalogId = B.CatalogId inner join PRODUCTS AS D ON C.CUID = D.CUID")
  File "/Users/arpitasaha/opt/anaconda3/lib/python3.7/site-packages/airflow/hooks/dbapi_hook.py", line 99, in get_pandas_df
    with closing(self.get_conn()) as conn:
  File "/Users/arpitasaha/opt/anaconda3/lib/python3.7/site-packages/airflow/hooks/sqlite_hook.py", line 40, in get_conn
    conn = sqlite3.connect(conn.host)
sqlite3.OperationalError: unable to open database file
[2020-10-19 22:16:09,151] {taskinstance.py:1194} INFO - Marking task as FAILED. dag_id=tutorial, task_id=sqlite_to_df, execution_date=20201019T163015, start_date=20201019T164609, end_date=20201019T164609
[2020-10-19 22:16:09,160] {configuration.py:338} WARNING - section/key [smtp/smtp_user] not found in config
[2020-10-19 22:16:09,161] {configuration.py:338} WARNING - section/key [smtp/smtp_user] not found in config
[2020-10-19 22:16:09,162] {taskinstance.py:1200} ERROR - Failed to send email to: ['arpita.b.saha@outlook.com']
[2020-10-19 22:16:09,162] {taskinstance.py:1201} ERROR - [Errno 61] Connection refused
Traceback (most recent call last):
  File "/Users/arpitasaha/opt/anaconda3/lib/python3.7/site-packages/airflow/models/taskinstance.py", line 984, in _run_raw_task
    result = task_copy.execute(context=context)
  File "/Users/arpitasaha/opt/anaconda3/lib/python3.7/site-packages/airflow/operators/python_operator.py", line 113, in execute
    return_value = self.execute_callable()
  File "/Users/arpitasaha/opt/anaconda3/lib/python3.7/site-packages/airflow/operators/python_operator.py", line 118, in execute_callable
    return self.python_callable(*self.op_args, **self.op_kwargs)
  File "/Users/arpitasaha/airflow/dags/tutorial.py", line 144, in getdf
    df = h.get_pandas_df("SELECT A.DocumentNo, A.FullName, A.Device, A.Country, B.OrderId, B.DocumentNo, B.OrderDate, B.CatalogId,C.CatalogId, C.ProductId, C.CUID, D.ProductId, D.ProductName, D.CUID FROM CUSTOMERS as A inner join ORDERS as B on A.DocumentNo = B.DocumentNo inner join CATALOG as C on C.CatalogId = B.CatalogId inner join PRODUCTS AS D ON C.CUID = D.CUID")
  File "/Users/arpitasaha/opt/anaconda3/lib/python3.7/site-packages/airflow/hooks/dbapi_hook.py", line 99, in get_pandas_df
    with closing(self.get_conn()) as conn:
  File "/Users/arpitasaha/opt/anaconda3/lib/python3.7/site-packages/airflow/hooks/sqlite_hook.py", line 40, in get_conn
    conn = sqlite3.connect(conn.host)
sqlite3.OperationalError: unable to open database file

During handling of the above exception, another exception occurred:

Traceback (most recent call last):
  File "/Users/arpitasaha/opt/anaconda3/lib/python3.7/site-packages/airflow/models/taskinstance.py", line 1473, in email_alert
    send_email(self.task.email, subject, html_content)
  File "/Users/arpitasaha/opt/anaconda3/lib/python3.7/site-packages/airflow/utils/email.py", line 62, in send_email
    mime_subtype=mime_subtype, mime_charset=mime_charset, **kwargs)
  File "/Users/arpitasaha/opt/anaconda3/lib/python3.7/site-packages/airflow/utils/email.py", line 108, in send_email_smtp
    send_MIME_email(smtp_mail_from, recipients, msg, dryrun)
  File "/Users/arpitasaha/opt/anaconda3/lib/python3.7/site-packages/airflow/utils/email.py", line 127, in send_MIME_email
    s = smtplib.SMTP_SSL(SMTP_HOST, SMTP_PORT) if SMTP_SSL else smtplib.SMTP(SMTP_HOST, SMTP_PORT)
  File "/Users/arpitasaha/opt/anaconda3/lib/python3.7/smtplib.py", line 251, in __init__
    (code, msg) = self.connect(host, port)
  File "/Users/arpitasaha/opt/anaconda3/lib/python3.7/smtplib.py", line 336, in connect
    self.sock = self._get_socket(host, port, self.timeout)
  File "/Users/arpitasaha/opt/anaconda3/lib/python3.7/smtplib.py", line 307, in _get_socket
    self.source_address)
  File "/Users/arpitasaha/opt/anaconda3/lib/python3.7/socket.py", line 728, in create_connection
    raise err
  File "/Users/arpitasaha/opt/anaconda3/lib/python3.7/socket.py", line 716, in create_connection
    sock.connect(sa)
ConnectionRefusedError: [Errno 61] Connection refused

During handling of the above exception, another exception occurred:

Traceback (most recent call last):
  File "/Users/arpitasaha/opt/anaconda3/lib/python3.7/site-packages/airflow/models/taskinstance.py", line 1198, in handle_failure
    self.email_alert(error)
  File "/Users/arpitasaha/opt/anaconda3/lib/python3.7/site-packages/airflow/models/taskinstance.py", line 1475, in email_alert
    send_email(self.task.email, subject, html_content_err)
  File "/Users/arpitasaha/opt/anaconda3/lib/python3.7/site-packages/airflow/utils/email.py", line 62, in send_email
    mime_subtype=mime_subtype, mime_charset=mime_charset, **kwargs)
  File "/Users/arpitasaha/opt/anaconda3/lib/python3.7/site-packages/airflow/utils/email.py", line 108, in send_email_smtp
    send_MIME_email(smtp_mail_from, recipients, msg, dryrun)
  File "/Users/arpitasaha/opt/anaconda3/lib/python3.7/site-packages/airflow/utils/email.py", line 127, in send_MIME_email
    s = smtplib.SMTP_SSL(SMTP_HOST, SMTP_PORT) if SMTP_SSL else smtplib.SMTP(SMTP_HOST, SMTP_PORT)
  File "/Users/arpitasaha/opt/anaconda3/lib/python3.7/smtplib.py", line 251, in __init__
    (code, msg) = self.connect(host, port)
  File "/Users/arpitasaha/opt/anaconda3/lib/python3.7/smtplib.py", line 336, in connect
    self.sock = self._get_socket(host, port, self.timeout)
  File "/Users/arpitasaha/opt/anaconda3/lib/python3.7/smtplib.py", line 307, in _get_socket
    self.source_address)
  File "/Users/arpitasaha/opt/anaconda3/lib/python3.7/socket.py", line 728, in create_connection
    raise err
  File "/Users/arpitasaha/opt/anaconda3/lib/python3.7/socket.py", line 716, in create_connection
    sock.connect(sa)
ConnectionRefusedError: [Errno 61] Connection refused
[2020-10-19 22:16:14,076] {local_task_job.py:102} INFO - Task exited with return code 1
